Traceback (most recent call last):
  File "/home/dario/miniconda3/envs/scientificProject2/lib/python3.10/site-packages/jupyter_cache/executors/utils.py", line 58, in single_nb_execution
    executenb(
  File "/home/dario/miniconda3/envs/scientificProject2/lib/python3.10/site-packages/nbclient/client.py", line 1204, in execute
    return NotebookClient(nb=nb, resources=resources, km=km, **kwargs).execute()
  File "/home/dario/miniconda3/envs/scientificProject2/lib/python3.10/site-packages/nbclient/util.py", line 84, in wrapped
    return just_run(coro(*args, **kwargs))
  File "/home/dario/miniconda3/envs/scientificProject2/lib/python3.10/site-packages/nbclient/util.py", line 62, in just_run
    return loop.run_until_complete(coro)
  File "/home/dario/miniconda3/envs/scientificProject2/lib/python3.10/asyncio/base_events.py", line 649, in run_until_complete
    return future.result()
  File "/home/dario/miniconda3/envs/scientificProject2/lib/python3.10/site-packages/nbclient/client.py", line 663, in async_execute
    await self.async_execute_cell(
  File "/home/dario/miniconda3/envs/scientificProject2/lib/python3.10/site-packages/nbclient/client.py", line 965, in async_execute_cell
    await self._check_raise_for_error(cell, cell_index, exec_reply)
  File "/home/dario/miniconda3/envs/scientificProject2/lib/python3.10/site-packages/nbclient/client.py", line 862, in _check_raise_for_error
    raise CellExecutionError.from_cell_and_msg(cell, exec_reply_content)
nbclient.exceptions.CellExecutionError: An error occurred while executing the following cell:
------------------
fig = go.line(pd_total_permits_and_request, x='Jaar', y=['Verblijfsvergunningen','Totaal asielverzoeken (aantal)'],
              title='Verblijfsvergunningen toegekend voor asiel voor bepaalde tijd per maand')

fig.update_layout(
    xaxis=dict(
        color='rgb(42,63,95)'
    ),
    yaxis=dict(
        type='linear',
        color='rgb(42,63,95)',
        title=dict(
        text='waardes',
        font=dict(
            color='rgb(42,63,95)'
        ),

    ),

    ),
    paper_bgcolor='white',
    plot_bgcolor='#e8ecf4',
    title=dict(
        text='Verblijfsvergunningen toegekend voor asiel voor bepaalde tijd per maand',
        font=dict(
            color='rgb(42,63,95)'
        )
    ),
    showlegend=True,
    height=600,
legend=dict(
        font=dict(
            color='rgb(42,63,95)'
        ),
        bgcolor='white',
    ))

fig.show()

#Belanrijk!!: Generatieve Kunstmatige intelligentie (KI) (ChatGPT met GPT 3.5) was gebruikt voor het creÃ«ren van deze opdracht. Met als doel het genereren van nieuwe, en het verbeteren van bestaande code. Zie de promps en terug gekregen antwoorden in het blok beneden.

------------------

[0;31m---------------------------------------------------------------------------[0m
[0;31mAttributeError[0m                            Traceback (most recent call last)
Cell [0;32mIn[7], line 1[0m
[0;32m----> 1[0m fig [38;5;241m=[39m [43mgo[49m[38;5;241;43m.[39;49m[43mline[49m(pd_total_permits_and_request, x[38;5;241m=[39m[38;5;124m'[39m[38;5;124mJaar[39m[38;5;124m'[39m, y[38;5;241m=[39m[[38;5;124m'[39m[38;5;124mVerblijfsvergunningen[39m[38;5;124m'[39m,[38;5;124m'[39m[38;5;124mTotaal asielverzoeken (aantal)[39m[38;5;124m'[39m],
[1;32m      2[0m               title[38;5;241m=[39m[38;5;124m'[39m[38;5;124mVerblijfsvergunningen toegekend voor asiel voor bepaalde tijd per maand[39m[38;5;124m'[39m)
[1;32m      4[0m fig[38;5;241m.[39mupdate_layout(
[1;32m      5[0m     xaxis[38;5;241m=[39m[38;5;28mdict[39m(
[1;32m      6[0m         color[38;5;241m=[39m[38;5;124m'[39m[38;5;124mrgb(42,63,95)[39m[38;5;124m'[39m
[0;32m   (...)[0m
[1;32m     34[0m         bgcolor[38;5;241m=[39m[38;5;124m'[39m[38;5;124mwhite[39m[38;5;124m'[39m,
[1;32m     35[0m     ))
[1;32m     37[0m fig[38;5;241m.[39mshow()

File [0;32m~/miniconda3/envs/scientificProject2/lib/python3.10/site-packages/plotly/graph_objects/__init__.py:299[0m, in [0;36m__getattr__[0;34m(import_name)[0m
[1;32m    295[0m         [38;5;28;01mfrom[39;00m [38;5;21;01m.[39;00m[38;5;21;01m.[39;00m[38;5;21;01mmissing_ipywidgets[39;00m [38;5;28;01mimport[39;00m FigureWidget
[1;32m    297[0m         [38;5;28;01mreturn[39;00m FigureWidget
[0;32m--> 299[0m [38;5;28;01mreturn[39;00m [43morig_getattr[49m[43m([49m[43mimport_name[49m[43m)[49m

File [0;32m~/miniconda3/envs/scientificProject2/lib/python3.10/site-packages/_plotly_utils/importers.py:39[0m, in [0;36mrelative_import.<locals>.__getattr__[0;34m(import_name)[0m
[1;32m     36[0m     class_module [38;5;241m=[39m importlib[38;5;241m.[39mimport_module(rel_module, parent_name)
[1;32m     37[0m     [38;5;28;01mreturn[39;00m [38;5;28mgetattr[39m(class_module, class_name)
[0;32m---> 39[0m [38;5;28;01mraise[39;00m [38;5;167;01mAttributeError[39;00m(
[1;32m     40[0m     [38;5;124m"[39m[38;5;124mmodule [39m[38;5;132;01m{__name__!r}[39;00m[38;5;124m has no attribute [39m[38;5;132;01m{name!r}[39;00m[38;5;124m"[39m[38;5;241m.[39mformat(
[1;32m     41[0m         name[38;5;241m=[39mimport_name, [38;5;18m__name__[39m[38;5;241m=[39mparent_name
[1;32m     42[0m     )
[1;32m     43[0m )

[0;31mAttributeError[0m: module 'plotly.graph_objects' has no attribute 'line'
AttributeError: module 'plotly.graph_objects' has no attribute 'line'

